<?xml version='1.0' encoding='utf-8'?>
<robot name="re-assemble">
    <link name="Base_08q-v1">
        <inertial>
            <origin xyz="-4.044211014209581e-06 0.020995018451609077 0.016257398321927876" rpy="0.0 0.0 0.0" />
            <mass value="0.9473651568999556" />
            <inertia ixx="0.0008496739425766244" iyy="0.0010681065322811346" izz="0.0010112658131779446" ixy="1.6108041988577255e-07" iyz="0.00016843792093824102" ixz="3.459533900838331e-08" />
        </inertial>
        <visual name="Base_08q-v1_visual">
            <origin xyz="0.0 0.0 0.0" rpy="0.0 0.0 0.0" />
            <geometry>
                <mesh filename="meshes/Base_08q-v1.stl" scale="0.001 0.001 0.001" />
            </geometry>
        </visual>
        <collision name="Base_08q-v1_collision">
            <origin xyz="0.0 0.0 0.0" rpy="0.0 0.0 0.0" />
            <geometry>
                <mesh filename="meshes/Base_08q-v1.stl" scale="0.001 0.001 0.001" />
            </geometry>
        </collision>
    </link>
    <link name="STS3215_03a-v2">
        <inertial>
            <origin xyz="-0.0003009753018927546 9.099337304272638e-15 0.00012706404393911786" rpy="0.0 0.0 0.0" />
            <mass value="0.28430342154966426" />
            <inertia ixx="3.972529005645275e-05" iyy="7.348830383489989e-05" izz="6.1536839124182e-05" ixy="5.272499314913768e-17" iyz="-4.04892931937727e-17" ixz="-5.568984350147366e-07" />
        </inertial>
        <visual name="STS3215_03a-v2_visual">
            <origin xyz="0.0 0.0 0.0" rpy="0.0 0.0 0.0" />
            <geometry>
                <mesh filename="meshes/STS3215_03a-v2.stl" scale="0.001 0.001 0.001" />
            </geometry>
        </visual>
        <collision name="STS3215_03a-v2_collision">
            <origin xyz="0.0 0.0 0.0" rpy="0.0 0.0 0.0" />
            <geometry>
                <mesh filename="meshes/STS3215_03a-v2.stl" scale="0.001 0.001 0.001" />
            </geometry>
        </collision>
    </link>
    <link name="Motor1_holder-v1">
        <inertial>
            <origin xyz="-1.740564512860416e-09 0.05071242889376458 0.011738360359638064" rpy="0.0 0.0 0.0" />
            <mass value="0.18685419312155607" />
            <inertia ixx="0.0001435489939205101" iyy="0.0001831783085190978" izz="6.274647122750537e-05" ixy="3.642031505114336e-12" iyz="9.88910000646033e-06" ixz="-1.0555509631124378e-11" />
        </inertial>
        <visual name="Motor1_holder-v1_visual">
            <origin xyz="0.0 0.0 0.0" rpy="0.0 0.0 0.0" />
            <geometry>
                <mesh filename="meshes/Motor1_holder-v1.stl" scale="0.001 0.001 0.001" />
            </geometry>
        </visual>
        <collision name="Motor1_holder-v1_collision">
            <origin xyz="0.0 0.0 0.0" rpy="0.0 0.0 0.0" />
            <geometry>
                <mesh filename="meshes/Motor1_holder-v1.stl" scale="0.001 0.001 0.001" />
            </geometry>
        </collision>
    </link>
    <link name="Rotation_Pitch_08i-v1">
        <inertial>
            <origin xyz="-0.021519084521298536 -0.02308197675587735 -0.007540448012893632" rpy="0.0 -0.0 0.0" />
            <mass value="0.5385464072796393" />
            <inertia ixx="0.00035989275036036553" iyy="0.00035561847715824286" izz="0.00015416093033730142" ixy="-1.71115945226865e-05" iyz="2.4190596915803783e-05" ixz="2.6897759597831368e-05" />
        </inertial>
        <visual name="Rotation_Pitch_08i-v1_visual">
            <origin xyz="0.008107082591089096 0.008847328248870915 -0.046399999999999775" rpy="1.5707963267948966 -2.0434154084839005e-15 0.8290313725909866" />
            <geometry>
                <mesh filename="meshes/Rotation_Pitch_08i-v1.stl" scale="0.001 0.001 0.001" />
            </geometry>
        </visual>
        <collision name="Rotation_Pitch_08i-v1_collision">
            <origin xyz="0.008107082591089096 0.008847328248870915 -0.046399999999999775" rpy="1.5707963267948966 -2.0434154084839005e-15 0.8290313725909866" />
            <geometry>
                <mesh filename="meshes/Rotation_Pitch_08i-v1.stl" scale="0.001 0.001 0.001" />
            </geometry>
        </collision>
    </link>
    <link name="STS3215_03a-v2">
        <inertial>
            <origin xyz="-0.00030097530189275 9.09827838600134e-15 0.00012706404393911754" rpy="0.0 0.0 0.0" />
            <mass value="0.28430342154966426" />
            <inertia ixx="3.9725290056452804e-05" iyy="7.348830383490049e-05" izz="6.15368391241825e-05" ixy="5.269614677180664e-17" iyz="-4.1267445190230036e-17" ixz="-5.568984350146729e-07" />
        </inertial>
        <visual name="STS3215_03a-v2_visual">
            <origin xyz="0.0 0.0 0.0" rpy="0.0 0.0 0.0" />
            <geometry>
                <mesh filename="meshes/STS3215_03a-v2.stl" scale="0.001 0.001 0.001" />
            </geometry>
        </visual>
        <collision name="STS3215_03a-v2_collision">
            <origin xyz="0.0 0.0 0.0" rpy="0.0 0.0 0.0" />
            <geometry>
                <mesh filename="meshes/STS3215_03a-v2.stl" scale="0.001 0.001 0.001" />
            </geometry>
        </collision>
    </link>
    <link name="SO_ARM100_08k-v1">
        <inertial>
            <origin xyz="-0.03990811707343907 -0.036444211703695745 4.982211753142347e-05" rpy="0.0 0.0 0.0" />
            <mass value="0.1085306279896827" />
            <inertia ixx="5.824313681198819e-05" iyy="4.591974108732388e-05" izz="2.6819364359594073e-05" ixy="-5.2975841060067986e-08" iyz="-1.747781357584806e-07" ixz="-1.9180971998408238e-07" />
        </inertial>
        <visual name="SO_ARM100_08k-v1_visual">
            <origin xyz="0.0 0.0 0.0" rpy="0.0 0.0 0.0" />
            <geometry>
                <mesh filename="meshes/SO_ARM100_08k-v1.stl" scale="0.001 0.001 0.001" />
            </geometry>
        </visual>
        <collision name="SO_ARM100_08k-v1_collision">
            <origin xyz="0.0 0.0 0.0" rpy="0.0 0.0 0.0" />
            <geometry>
                <mesh filename="meshes/SO_ARM100_08k-v1.stl" scale="0.001 0.001 0.001" />
            </geometry>
        </collision>
    </link>
    <link name="SO_ARM100_08k-1-v1">
        <inertial>
            <origin xyz="0.023496032656505586 -0.052581526396647246 -0.019498765636972556" rpy="0.0 -0.0 0.0" />
            <mass value="0.990624876519019" />
            <inertia ixx="0.0009625287348552225" iyy="0.0008903007727480879" izz="0.0015098897250297963" ixy="0.00032229195894072977" iyz="-0.0002662342172833932" ixz="0.00024100526674640003" />
        </inertial>
        <visual name="SO_ARM100_08k-1-v1_visual">
            <origin xyz="0.03067335913434227 -0.06041349786964692 -0.01098406556020363" rpy="-1.5707963267948861 -0.3490658561204986 2.312561280998798" />
            <geometry>
                <mesh filename="meshes/SO_ARM100_08k-1-v1.stl" scale="0.001 0.001 0.001" />
            </geometry>
        </visual>
        <collision name="SO_ARM100_08k-1-v1_collision">
            <origin xyz="0.03067335913434227 -0.06041349786964692 -0.01098406556020363" rpy="-1.5707963267948861 -0.3490658561204986 2.312561280998798" />
            <geometry>
                <mesh filename="meshes/SO_ARM100_08k-1-v1.stl" scale="0.001 0.001 0.001" />
            </geometry>
        </collision>
    </link>
    <link name="STS3215_03a-v2">
        <inertial>
            <origin xyz="-0.00039270806660438143 0.002106613445693695 -0.026652854396366853" rpy="9.860761315262648e-32 -0.0 0.0" />
            <mass value="0.28430342154966426" />
            <inertia ixx="6.205389247658462e-05" iyy="6.607626336686926e-05" izz="4.662027717208498e-05" ixy="-8.213725036301548e-06" iyz="2.60050543445452e-06" ixz="1.0662272298415316e-05" />
        </inertial>
        <visual name="STS3215_03a-v2_visual">
            <origin xyz="-0.0001756540681305019 0.002268351717108219 -0.02683577431577955" rpy="2.7635253059101053 0.9752657385459939 0.466240523217213" />
            <geometry>
                <mesh filename="meshes/STS3215_03a-v2.stl" scale="0.001 0.001 0.001" />
            </geometry>
        </visual>
        <collision name="STS3215_03a-v2_collision">
            <origin xyz="-0.0001756540681305019 0.002268351717108219 -0.02683577431577955" rpy="2.7635253059101053 0.9752657385459939 0.466240523217213" />
            <geometry>
                <mesh filename="meshes/STS3215_03a-v2.stl" scale="0.001 0.001 0.001" />
            </geometry>
        </collision>
    </link>
    <link name="Wrist_Roll_Pitch_08i-v1">
        <inertial>
            <origin xyz="-0.025731716586615504 -0.0035801735466113004 -0.02187453260448585" rpy="0.0 -0.0 9.840800675009029e-35" />
            <mass value="0.23921330884627623" />
            <inertia ixx="0.00013986623619213073" iyy="0.00015265327055264538" izz="0.00014880402495470648" ixy="-3.052900384834589e-05" iyz="2.119304571434492e-05" ixz="-2.7014651774502976e-05" />
        </inertial>
        <visual name="Wrist_Roll_Pitch_08i-v1_visual">
            <origin xyz="-0.023887366628743325 -0.0007229025384485866 -0.02324825343539299" rpy="-0.5911599278166635 -1.0303190766850475e-14 -2.39982769938589" />
            <geometry>
                <mesh filename="meshes/Wrist_Roll_Pitch_08i-v1.stl" scale="0.001 0.001 0.001" />
            </geometry>
        </visual>
        <collision name="Wrist_Roll_Pitch_08i-v1_collision">
            <origin xyz="-0.023887366628743325 -0.0007229025384485866 -0.02324825343539299" rpy="-0.5911599278166635 -1.0303190766850475e-14 -2.39982769938589" />
            <geometry>
                <mesh filename="meshes/Wrist_Roll_Pitch_08i-v1.stl" scale="0.001 0.001 0.001" />
            </geometry>
        </collision>
    </link>
    <link name="STS3215_03a-v2">
        <inertial>
            <origin xyz="0.020117668584090538 -0.009281276748084509 -0.0015383069115750736" rpy="0.0 -0.0 0.0" />
            <mass value="0.28430342154966426" />
            <inertia ixx="5.375031569740164e-05" iyy="6.488993034926587e-05" izz="5.611018696886517e-05" ixy="1.3004170095072536e-05" iyz="-4.749031802785345e-06" ixz="8.202324240548216e-06" />
        </inertial>
        <visual name="STS3215_03a-v2_visual">
            <origin xyz="0.01984792378806655 -0.009099815028448434 -0.0015060455889690516" rpy="-0.04414881966995711 -0.49805123599083034 2.566664124429131" />
            <geometry>
                <mesh filename="meshes/STS3215_03a-v2.stl" scale="0.001 0.001 0.001" />
            </geometry>
        </visual>
        <collision name="STS3215_03a-v2_collision">
            <origin xyz="0.01984792378806655 -0.009099815028448434 -0.0015060455889690516" rpy="-0.04414881966995711 -0.49805123599083034 2.566664124429131" />
            <geometry>
                <mesh filename="meshes/STS3215_03a-v2.stl" scale="0.001 0.001 0.001" />
            </geometry>
        </collision>
    </link>
    <link name="SO_ARM100_08k_elbow_rotate-v1">
        <inertial>
            <origin xyz="-0.010939594330009555 -0.011101282442867025 0.024873419870669444" rpy="0.0 -0.0 -4.419928812356213e-34" />
            <mass value="0.40041047035082356" />
            <inertia ixx="0.00018923448185694317" iyy="0.0001491926580524626" izz="0.00016475627533249674" ixy="2.58150573056363e-05" iyz="9.292129319612356e-06" ixz="2.358662702505071e-05" />
        </inertial>
        <visual name="SO_ARM100_08k_elbow_rotate-v1_visual">
            <origin xyz="-0.02420008865664415 -0.011617835658518861 -0.013511314170523966" rpy="-1.2314648868337803 0.9610403730026656 0.8172337352733353" />
            <geometry>
                <mesh filename="meshes/SO_ARM100_08k_elbow_rotate-v1.stl" scale="0.001 0.001 0.001" />
            </geometry>
        </visual>
        <collision name="SO_ARM100_08k_elbow_rotate-v1_collision">
            <origin xyz="-0.02420008865664415 -0.011617835658518861 -0.013511314170523966" rpy="-1.2314648868337803 0.9610403730026656 0.8172337352733353" />
            <geometry>
                <mesh filename="meshes/SO_ARM100_08k_elbow_rotate-v1.stl" scale="0.001 0.001 0.001" />
            </geometry>
        </collision>
    </link>
    <link name="STS3215_03a-v2">
        <inertial>
            <origin xyz="-0.018783535795312396 -0.011522896338229229 -0.0065087402020324705" rpy="8.604547553883294e-19 -0.0 -1.3082363541636962e-18" />
            <mass value="0.28430342154966426" />
            <inertia ixx="6.969224396952848e-05" iyy="5.966273654914875e-05" izz="4.539545249685106e-05" ixy="-6.214656034759875e-06" iyz="-6.5284586909105775e-06" ixz="-7.941937964831948e-06" />
        </inertial>
        <visual name="STS3215_03a-v2_visual">
            <origin xyz="-0.018904773305010565 -0.01175281137754956 -0.0067066592373679155" rpy="2.7709808316706535 1.0333843046831044 -2.2340504449166243" />
            <geometry>
                <mesh filename="meshes/STS3215_03a-v2.stl" scale="0.001 0.001 0.001" />
            </geometry>
        </visual>
        <collision name="STS3215_03a-v2_collision">
            <origin xyz="-0.018904773305010565 -0.01175281137754956 -0.0067066592373679155" rpy="2.7709808316706535 1.0333843046831044 -2.2340504449166243" />
            <geometry>
                <mesh filename="meshes/STS3215_03a-v2.stl" scale="0.001 0.001 0.001" />
            </geometry>
        </collision>
    </link>
    <link name="STS3215_03a-v2">
        <inertial>
            <origin xyz="-0.0003009753018927606 9.127979405318398e-15 0.00012706404393912453" rpy="0.0 0.0 0.0" />
            <mass value="0.28430342154966426" />
            <inertia ixx="3.972529005644802e-05" iyy="7.348830383489999e-05" izz="6.1536839124176e-05" ixy="5.22068757040188e-17" iyz="-3.820457405295796e-17" ixz="-5.568984350132477e-07" />
        </inertial>
        <visual name="STS3215_03a-v2_visual">
            <origin xyz="0.0 0.0 0.0" rpy="0.0 0.0 0.0" />
            <geometry>
                <mesh filename="meshes/STS3215_03a-v2.stl" scale="0.001 0.001 0.001" />
            </geometry>
        </visual>
        <collision name="STS3215_03a-v2_collision">
            <origin xyz="0.0 0.0 0.0" rpy="0.0 0.0 0.0" />
            <geometry>
                <mesh filename="meshes/STS3215_03a-v2.stl" scale="0.001 0.001 0.001" />
            </geometry>
        </collision>
    </link>
    <link name="Wrist_Roll_Pitch_08i-v1">
        <inertial>
            <origin xyz="-0.03285867489301218 -0.004140085160882636 -0.0075233458272168366" rpy="0.0 -0.0 0.0" />
            <mass value="0.23921330884627623" />
            <inertia ixx="0.00012131823174440712" iyy="0.00012504994511278525" izz="0.00019495535484228595" ixy="-6.171082650044426e-06" iyz="-8.393091488797228e-06" ixz="-1.802624789472731e-05" />
        </inertial>
        <visual name="Wrist_Roll_Pitch_08i-v1_visual">
            <origin xyz="-0.032558919051198384 -0.0005026028931949389 -0.0071605752523151624" rpy="-1.4353926298110002 0.19178981863390873 -2.1063514062616564" />
            <geometry>
                <mesh filename="meshes/Wrist_Roll_Pitch_08i-v1.stl" scale="0.001 0.001 0.001" />
            </geometry>
        </visual>
        <collision name="Wrist_Roll_Pitch_08i-v1_collision">
            <origin xyz="-0.032558919051198384 -0.0005026028931949389 -0.0071605752523151624" rpy="-1.4353926298110002 0.19178981863390873 -2.1063514062616564" />
            <geometry>
                <mesh filename="meshes/Wrist_Roll_Pitch_08i-v1.stl" scale="0.001 0.001 0.001" />
            </geometry>
        </collision>
    </link>
    <link name="Wrist_Roll_08c-v1-v2_Component1">
        <inertial>
            <origin xyz="-0.012892330964958527 -0.001324065814658039 0.019280963636584207" rpy="0.0 0.0 0.0" />
            <mass value="0.23136285040703947" />
            <inertia ixx="8.2186085734141e-05" iyy="8.451450873010677e-05" izz="0.00011752576506251808" ixy="4.369128477505542e-06" iyz="1.5716702204993696e-06" ixz="1.4345178888615471e-05" />
        </inertial>
        <visual name="Wrist_Roll_08c-v1-v2_Component1_visual">
            <origin xyz="0.0 0.0 0.0" rpy="0.0 0.0 0.0" />
            <geometry>
                <mesh filename="meshes/Wrist_Roll_08c-v1-v2_Component1.stl" scale="0.001 0.001 0.001" />
            </geometry>
        </visual>
        <collision name="Wrist_Roll_08c-v1-v2_Component1_collision">
            <origin xyz="0.0 0.0 0.0" rpy="0.0 0.0 0.0" />
            <geometry>
                <mesh filename="meshes/Wrist_Roll_08c-v1-v2_Component1.stl" scale="0.001 0.001 0.001" />
            </geometry>
        </collision>
    </link>
    <link name="STS3215_03a-v2">
        <inertial>
            <origin xyz="-0.02183202218730351 -0.0056629937076310985 0.0027828138860674302" rpy="-9.86076131526265e-32 -0.0 -8.628166150854818e-31" />
            <mass value="0.28430342154966426" />
            <inertia ixx="4.445949658839638e-05" iyy="6.665745989153273e-05" izz="6.363347653560577e-05" ixy="-1.050691002408807e-05" iyz="5.984982677278912e-06" ixz="1.5031346968229591e-06" />
        </inertial>
        <visual name="STS3215_03a-v2_visual">
            <origin xyz="-0.022060542384270826 -0.005829946472826686 0.0029460214146412155" rpy="2.6473811207713047 -0.17736286165430035 -2.725243918107495" />
            <geometry>
                <mesh filename="meshes/STS3215_03a-v2.stl" scale="0.001 0.001 0.001" />
            </geometry>
        </visual>
        <collision name="STS3215_03a-v2_collision">
            <origin xyz="-0.022060542384270826 -0.005829946472826686 0.0029460214146412155" rpy="2.6473811207713047 -0.17736286165430035 -2.725243918107495" />
            <geometry>
                <mesh filename="meshes/STS3215_03a-v2.stl" scale="0.001 0.001 0.001" />
            </geometry>
        </collision>
    </link>
    <link name="Moving_Jaw_08d-v1-v1">
        <inertial>
            <origin xyz="-0.0014240697711534623 -0.035163950016473634 0.0077384932680908845" rpy="0.0 -0.0 -7.703719777548943e-34" />
            <mass value="0.1586832108582172" />
            <inertia ixx="7.89354159006321e-05" iyy="3.248100528259641e-05" izz="6.938957265516027e-05" ixy="-1.5081518543719587e-05" iyz="-1.1854635606921642e-05" ixz="-1.0938761824759356e-05" />
        </inertial>
        <visual name="Moving_Jaw_08d-v1-v1_visual">
            <origin xyz="0.007011888548098604 -0.007118436381334155 0.01604278886971514" rpy="0.3469137307482232 0.4450346214789483 -0.09438204140106943" />
            <geometry>
                <mesh filename="meshes/Moving_Jaw_08d-v1-v1.stl" scale="0.001 0.001 0.001" />
            </geometry>
        </visual>
        <collision name="Moving_Jaw_08d-v1-v1_collision">
            <origin xyz="0.007011888548098604 -0.007118436381334155 0.01604278886971514" rpy="0.3469137307482232 0.4450346214789483 -0.09438204140106943" />
            <geometry>
                <mesh filename="meshes/Moving_Jaw_08d-v1-v1.stl" scale="0.001 0.001 0.001" />
            </geometry>
        </collision>
    </link>
    <joint name="STS3215_03a-v2_Revolute-2" type="continuous">
        <origin xyz="0.012500000386367267 9.58806177834247e-11 0.018700000000000036" rpy="0.0 -0.0 1.5707963267948983" />
        <parent link="STS3215_03a-v2" />
        <child link="Rotation_Pitch_08i-v1" />
        <axis xyz="0.0 0.0 1.0" />
    </joint>
    <joint name="STS3215_03a-v2_Revolute-4" type="continuous">
        <origin xyz="0.012500000670229827 2.1748424439138605e-09 -0.01769999647770381" rpy="-1.5707963267948821 0.8290313725909925 1.570796326794906" />
        <parent link="STS3215_03a-v2" />
        <child link="SO_ARM100_08k-1-v1" />
        <axis xyz="0.737277 0.67559 3.750277866033529e-17" />
    </joint>
    <joint name="SO_ARM100_08k-1-v1_Rigid-5" type="fixed">
        <origin xyz="0.07447060999999999 -0.08824607999999999 -0.034330419999999987" rpy="-1.0182257570545803e-15 0.7853981633974451 -3.9257550043977953e-16" />
        <parent link="SO_ARM100_08k-1-v1" />
        <child link="STS3215_03a-v2" />
    </joint>
    <joint name="STS3215_03a-v2_Revolute-7" type="continuous">
        <origin xyz="0.015315395479346936 0.017378339999999878 -0.027956300980211887" rpy="-3.389728535365244e-16 -0.785398163397447 3.2517679528326754e-17" />
        <parent link="STS3215_03a-v2" />
        <child link="Wrist_Roll_Pitch_08i-v1" />
        <axis xyz="0.737277 0.67559 -3.39776747869228e-17" />
    </joint>
    <joint name="Wrist_Roll_Pitch_08i-v1_Rigid-8" type="fixed">
        <origin xyz="-0.017504029999999997 0.0031162699999999965 -0.029442650000000015" rpy="2.3561944901923457 6.660975083332575e-10 -3.1415926529236957" />
        <parent link="Wrist_Roll_Pitch_08i-v1" />
        <child link="STS3215_03a-v2" />
    </joint>
    <joint name="STS3215_03a-v2_Revolute-9" type="continuous">
        <origin xyz="0.01767294000817094 -0.008673965731082376 0.02087761055724533" rpy="-0.785398163397447 4.338581489281525e-17 -3.141592652647789" />
        <parent link="STS3215_03a-v2" />
        <child link="SO_ARM100_08k_elbow_rotate-v1" />
        <axis xyz="-0.37652300000000005 -0.41090299999999996 0.830295" />
    </joint>
    <joint name="SO_ARM100_08k_elbow_rotate-v1_Rigid-12" type="fixed">
        <origin xyz="-0.02753993 -0.012037259999999996 0.03473309000000001" rpy="3.1415926535897922 0.7853981633974506 -3.1218382448969435" />
        <parent link="SO_ARM100_08k_elbow_rotate-v1" />
        <child link="STS3215_03a-v2" />
    </joint>
    <joint name="STS3215_03a-v2_Revolute-15" type="continuous">
        <origin xyz="-0.02651877752090119 -0.03191000591767831 -0.00899891325538654" rpy="-0.019750555373295158 -0.7852030704405512 -3.1136593337733354" />
        <parent link="STS3215_03a-v2" />
        <child link="Wrist_Roll_Pitch_08i-v1" />
        <axis xyz="0.500962 0.844217 0.19061599999999998" />
    </joint>
    <joint name="STS3215_03a-v2_Revolute-16" type="continuous">
        <origin xyz="0.012500004374636369 1.1984412395804612e-09 0.018699997382835055" rpy="-1.324799292993419 0.9954112014990447 0.4011360195493793" />
        <parent link="STS3215_03a-v2" />
        <child link="Wrist_Roll_08c-v1-v2" />
        <axis xyz="-0.8389830000000003 -0.5277760000000001 0.13251500000000002" />
    </joint>
    <joint name="Wrist_Roll_08c-v1-v2_Rigid-17" type="fixed">
        <origin xyz="-0.023070509999999995 -0.0021048899999999995 0.014495179999999977" rpy="-1.103971260012025e-15 -0.7853981633974496 1.5707963267948926" />
        <parent link="Wrist_Roll_08c-v1-v2" />
        <child link="STS3215_03a-v2" />
    </joint>
    <joint name="STS3215_03a-v2_Revolute-19" type="continuous">
        <origin xyz="-0.03955703826381589 -0.003868250000000062 -0.011052701243913141" rpy="-0.7853981633974496 -9.813077866773746e-17 -1.5707963267948977" />
        <parent link="STS3215_03a-v2" />
        <child link="Moving_Jaw_08d-v1-v1" />
        <axis xyz="-0.37100000000000005 0.376637 -0.848825" />
    </joint>
</robot>